Workbook

Sheet ReadMe
B1: DPDP COMPLIANCE FRAMEWORK
B2: OPERATIONAL GUIDE | READ THIS FIRST
B4: 1. WHAT IS THIS DOCUMENT & WHY IT EXISTS
C5: Document Identity | D5: This workbook is a complete, operationally-ready DPDP Compliance Framework built on India’s Digital Personal Data Protection Act, 2023 and the DPDP Rules, 2025. It is not a legal commentary or academic reference — it is a working instrument designed to be your organisation’s central compliance programme artefact from Day 1 through audit-readiness.
C6: Design Philosophy | D6: The framework bridges two gaps that commonly cause compliance programmes to stall: (a) the gap between legal interpretation and operational implementation, and (b) the gap between knowing what to do and knowing who does it, by when, and with what evidence. Every sheet in this workbook serves a distinct function in closing those gaps.
C7: Intended Users | D7: DPO / Privacy Office (primary owner) | CISO / InfoSec | Legal & Compliance | IT & Engineering leadership | HR leadership | Product & UX leads | Business Unit Heads | Procurement & Vendor Management | Board / Executive sponsors | External auditors (read-only for Assessment + Dashboard sheets).
C8: Scope & Coverage | D8: 73 primary compliance obligations across 12 categories with Control IDs, Priority tiers, DPDP Section mapping, and Penalty exposure (Assessment + Implementation) + 340 granular implementation-level controls (Granular Controls) + 55+ RACI-mapped control responsibilities + 26-question Express Evaluation for applicability determination + Live Compliance Dashboard with formula-driven KPIs pulling from the master tracker + Framework Guide with maturity model, lifecycle definitions, and BU bifurcation rules.
B10: 2. FRAMEWORK ARCHITECTURE — HOW THE SHEETS CONNECT
B11: The six sheets form a sequential, dependency-linked workflow. Each sheet feeds the next. Skipping sheets creates gaps that compound downstream. Follow the numbered sequence below.
B12: ❶ Express Evaluation | C12: ENTRY POINT. Determines which controls apply to your organisation. Drives everything downstream. Without this, teams implement controls that don’t apply — or worse, miss controls that do. | D12: OUTPUT: Completed evaluation with all 26 questions answered. Entity classification confirmed. Applicable domains identified.
B13: ❷ RACI Matrix | C13: OWNERSHIP LAYER. Assigns functional and business-unit responsibility to every control. Without clear ownership, controls remain orphaned and unimplemented. | D13: OUTPUT: Every control row has at least one ‘A’ (Accountable) and one ‘R’ (Responsible). BU columns populated if D6=Yes in Express Evaluation.
B14: ❸ Assessment + Implementation | C14: OPERATIONAL ENGINE. Enhanced with Control IDs, Categories (12 domains), Priority tiers (Critical/High/Medium/Low), DPDP Section references, and Max Penalty exposure. Assessment Area (cols K–O) captures current-state maturity. Implementation Area (cols P–U) drives remediation. Governance & Evidence (cols V–Y) tracks artefacts. Built-in Assessment Summary auto-calculates readiness by priority and category. | D14: OUTPUT: All 73 items assessed for current state. Gap descriptions documented. Action plans, owners, target dates, and budgets assigned for every non-compliant item.
B15: ❹ Granular Controls | C15: ENGINEERING LAYER. 340 discrete controls for teams building systems, configuring platforms, and writing policies. Each control now carries its own assessment and implementation tracking columns. | D15: OUTPUT: Granular controls filtered by applicability. Technical teams have specific, verifiable implementation targets.
B16: ❺ Compliance Dashboard | C16: GOVERNANCE VIEW. Formula-driven summary of programme health. Shows assessment status distribution, implementation progress, risk heat, and overall compliance/evidence readiness percentages. | D16: OUTPUT: Live dashboard reflecting real-time data from the Assessment + Implementation sheet. Board-reportable at any time.
B17: ❻ Framework Guide | C17: REFERENCE LAYER. Definitions, maturity model, lifecycle stages, RACI conventions, BU bifurcation guidance, and risk calibration. Consult when any term or concept is unclear. | D17: OUTPUT: Shared understanding across all stakeholders of what each term, status, and rating means.
B18: TIP | C18: Think of the sheets as layers of a pyramid: Express Evaluation is the foundation (scope), RACI is the structure (ownership), Assessment+Implementation is the operating floor (execution), Granular Controls are the building blocks (engineering), Dashboard is the roof (visibility), and the Guide is the blueprint (definitions).
B20: 3. STEP-BY-STEP EXECUTION PLAYBOOK — YOUR FIRST 30 DAYS
B21: Follow these steps in sequence. Each step has a defined owner, duration, and verifiable output. Do not proceed to the next step until the current step’s output is confirmed.
B22: STEP 1 | C22: ❶ COMPLETE THE EXPRESS EVALUATION (Sheet: Express Evaluation)
C23: WHAT: Convene a cross-functional kick-off with DPO, Legal, CISO, HR Head, and a senior business representative. Walk through all 26 questions across Sections A–D. Answer every question using the dropdown in Column E. Review the auto-computed Applicability Result in Column F and the mapped control domains in Column G.
C24: WHY: This is your compliance scope definition. Every subsequent sheet is filtered and prioritised based on these answers. An incorrect classification here (e.g., treating yourself as a standard DF when you’re an SDF) cascades into missed obligations across the entire programme.
C25: WHO: DPO / Privacy Office (facilitator) + Legal (classification advisor) + CISO (security scope) + HR (employment data) + Business Unit Heads (BU determination)
C26: DURATION: Half-day workshop (2–4 hours, including discussion and sign-off)
C27: OUTPUT: Signed-off Express Evaluation with all 26 responses. Entity classification documented. List of applicable control domains extracted for downstream filtering.
B28: >> | C28: Pro tip: Print or project the Express Evaluation during the kick-off. Make it a collaborative exercise, not a form-filling task. Disagreements at this stage are valuable — they surface scope ambiguities that would otherwise emerge as compliance gaps months later.
B30: STEP 2 | C30: ❷ CUSTOMISE THE RACI MATRIX (Sheet: RACI Matrix)
C31: WHAT: Using the Express Evaluation outputs, review each control row in the RACI Matrix. Confirm or adjust pre-populated RACI assignments to match your organisation’s actual structure. If Express Evaluation D6 = Yes (multiple BUs), populate the BU columns (M, N, O) with named roles from each business unit. Mark controls as ‘Not Applicable’ in the Risk Priority column if the Express Evaluation determined they’re out of scope.
C32: WHY: Without explicit ownership, controls exist on paper but not in practice. The RACI Matrix converts abstract obligations into named accountabilities. It also prevents the common failure mode where ‘everyone is responsible’ (meaning no one is).
C33: WHO: DPO / Privacy Office (orchestrator) + Each functional head confirms their ‘R’ and ‘A’ assignments + BU Heads nominate BU Privacy Champions and BU IT Leads
C34: DURATION: 1–2 working days (individual function reviews + one alignment meeting)
C35: OUTPUT: Fully customised RACI Matrix. Every applicable control has exactly one ‘A’ and at least one ‘R’. BU columns populated where applicable. Non-applicable controls marked.
B36: !! | C36: Common mistake: Assigning ‘A’ (Accountable) to more than one function per control. Accountability must be singular. If two functions share accountability, the control will fall between chairs during execution. Resolve dual-accountability during this step, not during an audit.
B38: STEP 3 | C38: ❸ CONDUCT BASELINE ASSESSMENT (Sheet: Assessment + Implementation — Assessment Area)
C39: WHAT: For each of the 73 compliance items, evaluate your current state using the Assessment Area columns (K–O). Set Assessment Status (Compliant / Partially Compliant / Non-Compliant / Not Assessed / Not Applicable). Set Maturity Level (L0–L4). Flag gaps in Column M. Describe each gap in Column N. Assign a Risk Rating (Critical / High / Medium / Low) in Column O based on enforcement exposure and operational impact.
C40: WHY: You cannot build a remediation plan without knowing your starting position. This step produces the gap register — the single most important artefact for programme planning, budgeting, and board reporting. It also immediately populates the Compliance Dashboard.
C41: WHO: DPO leads assessment + CISO assesses security controls (Items 12–17) + Legal assesses consent/notice/rights (Items 1–5, 56–62) + IT assesses technical controls + HR assesses employment controls
C42: DURATION: 1–2 weeks (assessment interviews, evidence collection, gap documentation)
C43: OUTPUT: Completed Assessment Area for all 73 items. Gap register with risk ratings. Dashboard showing current compliance posture. Board-ready baseline report.
B44: TIP | C44: Assess honestly. The temptation is to mark items as ‘Partially Compliant’ when they are closer to ‘Non-Compliant’. Use L0–L4 maturity as a forcing function: if no documented policy or procedure exists, it’s L0 (Absent), regardless of informal practices. Auditors will test against documented, verifiable evidence — not tribal knowledge.
B46: STEP 4 | C46: ❹ BUILD THE IMPLEMENTATION PLAN (Sheet: Assessment + Implementation — Implementation Area)
...

Sheet Express Evaluation
A1: DPDP COMPLIANCE FRAMEWORK — EXPRESS EVALUATION SHEET
A2: Purpose: Complete this evaluation to determine applicable compliance control domains, entity classification, and regulatory obligation scope under the DPDP Act 2023 & Rules 2025.
A3: Instructions: Answer each question using the Response column dropdown. The Applicability Result column auto-computes your applicable control domains. Complete Section A first — downstream sections depend on your entity classification.
A5: # | B5: Section | C5: Evaluation Question | D5: Response Options | E5: Your Response | F5: Applicability Result | G5: Applicable Control Domain(s) | H5: Compliance Worksheet Reference
A6: SECTION A — ENTITY CLASSIFICATION & ROLE DETERMINATION
A7: A1 | B7: Entity Classification | C7: Does your organisation determine the purpose and means of processing personal data? | D7: Yes / No | F7: =IF(E7="Yes","Data Fiduciary (DF)","Not a DF — reassess role") -> Not a DF — reassess role | G7: All DF controls (Items 1–74) | H7: Items 1–5, 12–17
A8: A2 | B8: Entity Classification | C8: Has the Central Government notified your organisation as a Significant Data Fiduciary (SDF)? | D8: Yes / No / Pending | F8: =IF(E8="Yes","SDF — enhanced obligations apply",IF(E8="Pending","Monitor notification status","Standard DF obligations")) -> Standard DF obligations | G8: SDF controls: DPO, DPIA, Audit, Algo Due-Diligence | H8: Items 49–55
A9: A3 | B9: Entity Classification | C9: Does your organisation intend to operate or currently operate as a Consent Manager? | D9: Yes / No | F9: =IF(E9="Yes","Consent Manager registration + operating obligations apply","CM controls not applicable") -> CM controls not applicable | G9: CM controls: Registration, Operations, Board Compliance | H9: Items 6–11
A10: A4 | B10: Entity Classification | C10: Does your organisation process personal data on behalf of another entity (as a Data Processor)? | D10: Yes / No | F10: =IF(E10="Yes","Processor — contractual + security obligations via DF","Not a Processor") -> Not a Processor | G10: Processor-facing controls in Items 16, 29 | H10: Items 16, 29
A11: A5 | B11: Entity Classification | C11: Is your organisation classified under Third Schedule (E-Commerce, E-Gaming, Social Media Intermediary)? | D11: Yes / No | F11: =IF(E11="Yes","Third Schedule retention + erasure rules apply","Standard retention rules apply") -> Standard retention rules apply | G11: Retention & Erasure: Items 24–28 | H11: Items 24–28
A12: SECTION B — PROCESSING SCOPE & DATA CATEGORIES
A13: B1 | B13: Processing Scope | C13: Does your organisation collect personal data directly from Data Principals (individuals)? | D13: Yes / No | F13: =IF(E13="Yes","Consent + Notice obligations apply","Assess if legitimate use applies") -> Assess if legitimate use applies | G13: Consent & Notice: A1–A2 series, Items 1–5 | H13: Items 1–5
A14: B2 | B14: Processing Scope | C14: Does your organisation process personal data based on legitimate use (Section 7) without consent? | D14: Yes / No | F14: =IF(E14="Yes","Legitimate Use controls apply — document basis per Sec 7","Consent-only processing") -> Consent-only processing | G14: Legitimate Use: B1–B6 series | H14: Item 1 (Legal Basis Register)
A15: B3 | B15: Processing Scope | C15: Does your organisation process personal data of children (under 18) or persons with disability? | D15: Yes / No | F15: =IF(E15="Yes","CRITICAL: Enhanced child/PWD data controls apply","Child data controls not required") -> Child data controls not required | G15: Children/PWD: Items 35–48, A4 series | H15: Items 35–48
A16: B4 | B16: Processing Scope | C16: Does your organisation transfer personal data outside India? | D16: Yes / No | F16: =IF(E16="Yes","Cross-border transfer controls + adequacy assessment required","Domestic processing only") -> Domestic processing only | G16: Cross-Border: Items 64–65 | H16: Items 64–65
A17: B5 | B17: Processing Scope | C17: Does your organisation process personal data for research, archiving, or statistical purposes? | D17: Yes / No | F17: =IF(E17="Yes","Second Schedule exemption framework applicable","Research exemption not relevant") -> Research exemption not relevant | G17: Research: Items 66–73 | H17: Items 66–73
A18: B6 | B18: Processing Scope | C18: Does your organisation use any Data Processors (third-party service providers processing data on your behalf)? | D18: Yes / No | F18: =IF(E18="Yes","Processor governance + contractual controls mandatory","Direct processing only") -> Direct processing only | G18: Processor Controls: Items 16, 29, B5 series | H18: Items 16, 29
A19: B7 | B19: Processing Scope | C19: Does your organisation process employee personal data (HR, payroll, biometrics, CCTV)? | D19: Yes / No | F19: =IF(E19="Yes","Employment legitimate use + biometric controls apply","Employment processing not in scope") -> Employment processing not in scope | G19: Employment: B5.1–B5.5 series, B2.9 | H19: Item 1 (Sec 7(i) basis)
A20: SECTION C — OPERATIONAL READINESS BASELINE
A21: C1 | B21: Operational Readiness | C21: Does your organisation have a documented privacy notice currently published? | D21: Yes / No / Partial | F21: =IF(E21="Yes","Verify against Rule 3/4 requirements",IF(E21="Partial","Gap remediation required","URGENT: Notice must be created")) -> URGENT: Notice must be created | G21: Notice: A1 series, Items 2, 5 | H21: Items 2, 5
A22: C2 | B22: Operational Readiness | C22: Does your organisation have a functioning consent capture and withdrawal mechanism? | D22: Yes / No / Partial | F22: =IF(E22="Yes","Validate against Sec 6 + Rule 4",IF(E22="Partial","Assess gaps in A6–A8 controls","URGENT: Consent mechanism required")) -> URGENT: Consent mechanism required | G22: Consent Ops: A2, A6–A8 series | H22: Items 3, 4
A23: C3 | B23: Operational Readiness | C23: Does your organisation have a documented breach notification process? | D23: Yes / No / Partial | F23: =IF(E23="Yes","Validate against Rule 7 timelines",IF(E23="Partial","Enhance per Items 18–23","CRITICAL: Breach playbook required")) -> CRITICAL: Breach playbook required | G23: Breach: Items 18–23, C1.1 series | H23: Items 18–23
A24: C4 | B24: Operational Readiness | C24: Does your organisation maintain a data processing inventory / Record of Processing Activities (RoPA)? | D24: Yes / No / Partial | F24: =IF(E24="Yes","Map to DPDP requirements",IF(E24="Partial","Expand to DPDP categories","FOUNDATIONAL: Build RoPA first")) -> FOUNDATIONAL: Build RoPA first | G24: Foundation for all controls | H24: All Items
A25: C5 | B25: Operational Readiness | C25: Does your organisation have a rights request handling mechanism (access, correction, erasure)? | D25: Yes / No / Partial | F25: =IF(E25="Yes","Verify against Sec 11–14 + Rule 14",IF(E25="Partial","Enhance per Items 56–62","REQUIRED: Rights mechanism needed")) -> REQUIRED: Rights mechanism needed | G25: Rights: Items 56–62 | H25: Items 56–62
A26: C6 | B26: Operational Readiness | C26: Does your organisation have security safeguards aligned to Rule 6 requirements? | D26: Yes / No / Partial | F26: =IF(E26="Yes","Validate encryption, ACL, logging, backup, monitoring",IF(E26="Partial","Gap assessment against Rule 6(a)–(g)","HIGH RISK: Security baseline required")) -> HIGH RISK: Security baseline required | G26: Security: Items 12–17, C1 series | H26: Items 12–17
A27: C7 | B27: Operational Readiness | C27: Does your organisation have a grievance redress mechanism published with SLA? | D27: Yes / No / Partial | F27: =IF(E27="Yes","Confirm ≤90-day SLA + publication",IF(E27="Partial","Publish mechanism per Rule 14(3)","REQUIRED: Grievance system needed")) -> REQUIRED: Grievance system needed | G27: Grievance: Items 61, 63 | H27: Items 61, 63
A28: C8 | B28: Operational Readiness | C28: Does your organisation have pre-existing (legacy) personal data collected before the Act? | D28: Yes / No / Unknown | F28: =IF(E28="Yes","Legacy consent migration required per Rule 3",IF(E28="Unknown","URGENT: Conduct data discovery","No legacy remediation needed")) -> No legacy remediation needed | G28: Legacy: A1.5, Item 2 | H28: Item 2
A29: SECTION D — SECTOR-SPECIFIC & BUSINESS UNIT APPLICABILITY
A30: D1 | B30: Sector Applicability | C30: Is your organisation a clinical/mental health establishment or healthcare professional? | D30: Yes / No | F30: =IF(E30="Yes","Fourth Schedule Part-A exemptions may apply for child data","Not applicable") -> Not applicable | G30: Items 36, 38–39 | H30: Items 36, 38–39
A31: D2 | B31: Sector Applicability | C31: Is your organisation an educational institution? | D31: Yes / No | F31: =IF(E31="Yes","Fourth Schedule Part-A exemption A3 applicable","Not applicable") -> Not applicable | G31: Item 40 | H31: Item 40
A32: D3 | B32: Sector Applicability | C32: Does your organisation operate a crèche, childcare centre, or child transport service? | D32: Yes / No | F32: =IF(E32="Yes","Fourth Schedule Part-A exemptions A4/A5 apply","Not applicable") -> Not applicable | G32: Items 41–42 | H32: Items 41–42
A33: D4 | B33: Sector Applicability | C33: Does your organisation process data for government scheme benefits delivery? | D33: Yes / No | F33: =IF(E33="Yes","Fourth Schedule Part-B exemption B2 applicable","Not applicable") -> Not applicable | G33: Item 43 | H33: Item 43
A34: D5 | B34: Sector Applicability | C34: Is your organisation subject to sectoral data localisation requirements (RBI, IRDAI, SEBI, CERT-In)? | D34: Yes / No / Unsure | F34: =IF(E34="Yes","Multi-layer compliance: DPDP + sectoral law",IF(E34="Unsure","Legal assessment required","DPDP-only compliance")) -> DPDP-only compliance | G34: Items 55, 65 | H34: Items 55, 65
A35: D6 | B35: Sector Applicability | C35: Does your organisation have multiple business units processing personal data independently? | D35: Yes / No | F35: =IF(E35="Yes","BU-level RACI + control ownership bifurcation required","Centralised compliance model sufficient") -> Centralised compliance model sufficient | G35: RACI Matrix — BU Layer | H35: All Items
A37: EVALUATION SUMMARY
A38: Entity Classification: | B38: =IF(E7="Yes","Data Fiduciary","") | C38: =IF(E8="Yes"," + Significant Data Fiduciary","") | D38: =IF(E9="Yes"," + Consent Manager","")
A39: Total Applicable Domains: | B39: Count responses marked 'Yes' across Sections A–D to determine scope
A40: Priority Implementation Areas: | B40: Domains where Section C responses are 'No' = highest priority
A41: Business Unit Bifurcation Required: | B41: =IF(E32="Yes","Yes — activate BU-level RACI columns","No — centralised model") -> No — centralised model

Sheet RACI Matrix
A1: DPDP COMPLIANCE FRAMEWORK — RACI RESPONSIBILITY MATRIX
A2: R = Responsible (executes) | A = Accountable (owns outcome) | C = Consulted (provides input) | I = Informed (kept updated) | BU columns enable business unit-level bifurcation of responsibilities
A3: CONTROL IDENTIFICATION | E3: CENTRAL / FUNCTIONAL OWNERSHIP (RACI) | M3: BUSINESS UNIT BIFURCATION (RACI) | P3: GOVERNANCE
A4: Control ID | B4: Domain | C4: Control / Obligation | D4: Trigger Event | E4: DPO / Privacy Office | F4: CISO / InfoSec | G4: Legal & Compliance | H4: IT / Engineering | I4: HR / People Ops | J4: Product / UX | K4: Procurement / Vendor Mgmt | L4: Business Operations | M4: BU Head (per BU) | N4: BU Privacy Champion | O4: BU IT Lead | P4: Board / Executive Sponsor | Q4: Risk Priority | R4: Implementation Phase
A5: CONSENT & NOTICE
A6: CN-01 | B6: Consent & Notice | C6: Identify Legal Basis for Processing (Consent or Legitimate Use) | D6: New/existing processing activity | E6: A | F6: C | G6: R | H6: C | I6: C | J6: C | K6: I | L6: C | M6: R | N6: C | O6: I | P6: I | Q6: P0 — Critical | R6: Phase 1
A7: CN-02 | B7: Consent & Notice | C7: Display & Serve Mandatory Standalone Notice | D7: Before requesting consent | E7: A | F7: I | G7: R | H7: R | I7: I | J7: R | K7: I | L7: C | M7: C | N7: I | O7: I | P7: I | Q7: P0 — Critical | R7: Phase 1
A8: CN-03 | B8: Consent & Notice | C8: Obtain Valid Consent (free, specific, informed, unequivocal) | D8: Consent-based processing initiation | E8: A | F8: C | G8: R | H8: R | I8: I | J8: R | K8: I | L8: I | M8: C | N8: C | O8: I | P8: I | Q8: P0 — Critical | R8: Phase 1
A9: CN-04 | B9: Consent & Notice | C9: Enable Consent Withdrawal & Stop Processing | D9: Withdrawal request received | E9: A | F9: C | G9: R | H9: R | I9: I | J9: R | K9: I | L9: I | M9: R | N9: C | O9: C | P9: I | Q9: P0 — Critical | R9: Phase 1
A10: CN-05 | B10: Consent & Notice | C10: Maintain Notice Content & Presentation Standard | D10: Creating/updating privacy notice | E10: A | F10: I | G10: R | H10: C | I10: I | J10: R | K10: I | L10: I | M10: C | N10: I | O10: I | P10: I | Q10: P1 — High | R10: Phase 1
A11: CONSENT MANAGER
A12: CM-01 | B12: Consent Manager | C12: Eligibility & Application Filing (Part A, First Schedule) | D12: Intent to operate as CM | E12: A | F12: C | G12: R | H12: R | I12: I | J12: I | K12: I | L12: C | M12: I | N12: I | O12: I | P12: A | Q12: P1 — High | R12: Phase 2
A13: CM-02 | B13: Consent Manager | C13: Board Evaluation & Decision Preparation | D13: Post application submission | E13: A | F13: C | G13: R | H13: C | I13: I | J13: I | K13: I | L13: I | M13: I | N13: I | O13: I | P13: I | Q13: P1 — High | R13: Phase 2
A14: CM-03 | B14: Consent Manager | C14: Registered CM Operating Obligations | D14: Post-registration operations | E14: A | F14: R | G14: R | H14: R | I14: I | J14: I | K14: I | L14: C | M14: I | N14: I | O14: I | P14: I | Q14: P0 — Critical | R14: Phase 2
A15: CM-04 | B15: Consent Manager | C15: Non-Adherence & Corrective Action Framework | D15: Board detects non-compliance | E15: A | F15: R | G15: R | H15: C | I15: I | J15: I | K15: I | L15: I | M15: I | N15: I | O15: I | P15: A | Q15: P1 — High | R15: Phase 2
A16: CM-05 | B16: Consent Manager | C16: Suspension / Cancellation Continuity Planning | D16: Serious breach or non-adherence | E16: A | F16: R | G16: R | H16: R | I16: I | J16: I | K16: I | L16: C | M16: I | N16: I | O16: I | P16: A | Q16: P1 — High | R16: Phase 2
A17: CM-06 | B17: Consent Manager | C17: Mandatory Information Disclosure to Board | D17: Board requests information | E17: A | F17: C | G17: R | H17: C | I17: I | J17: I | K17: I | L17: I | M17: I | N17: I | O17: I | P17: I | Q17: P1 — High | R17: Phase 2
A18: SECURITY SAFEGUARDS
A19: SS-01 | B19: Security Safeguards | C19: Implement Reasonable Security Safeguards (Rule 6 baseline) | D19: Processing/storing/transmitting PD | E19: C | F19: A | G19: C | H19: R | I19: I | J19: I | K19: C | L19: I | M19: C | N19: I | O19: R | P19: I | Q19: P0 — Critical | R19: Phase 1
A20: SS-02 | B20: Security Safeguards | C20: Access Control & Monitoring (Rule 6(b)(c)) | D20: Data access/modification/export | E20: C | F20: A | G20: I | H20: R | I20: C | J20: I | K20: I | L20: I | M20: C | N20: I | O20: R | P20: I | Q20: P0 — Critical | R20: Phase 1
A21: SS-03 | B21: Security Safeguards | C21: Data Availability, Integrity & Backup (Rule 6(d)) | D21: CIA risk to personal data | E21: C | F21: A | G21: I | H21: R | I21: I | J21: I | K21: I | L21: I | M21: I | N21: I | O21: R | P21: I | Q21: P0 — Critical | R21: Phase 1
A22: SS-04 | B22: Security Safeguards | C22: Log Retention & Breach Detection (Rule 6(e)) | D22: Breach/unauthorised access occurs or may occur | E22: C | F22: A | G22: C | H22: R | I22: I | J22: I | K22: I | L22: I | M22: C | N22: I | O22: R | P22: I | Q22: P0 — Critical | R22: Phase 1
A23: SS-05 | B23: Security Safeguards | C23: Security Obligations in Processor Contracts (Rule 6(f)) | D23: Using any Data Processor | E23: C | F23: A | G23: R | H23: C | I23: I | J23: I | K23: R | L23: I | M23: C | N23: I | O23: I | P23: I | Q23: P0 — Critical | R23: Phase 1
A24: SS-06 | B24: Security Safeguards | C24: Technical & Organisational Measures — Ongoing (Rule 6(g)) | D24: Continuous operations | E24: C | F24: A | G24: C | H24: R | I24: I | J24: I | K24: I | L24: I | M24: C | N24: I | O24: R | P24: I | Q24: P1 — High | R24: Phase 2
A25: BREACH NOTIFICATION
A26: BN-01 | B26: Breach Notification | C26: Breach Awareness & Activation (incl. Processor breach) | D26: Breach awareness | E26: R | F26: A | G26: R | H26: R | I26: I | J26: I | K26: C | L26: I | M26: R | N26: C | O26: R | P26: I | Q26: P0 — Critical | R26: Phase 1
A27: BN-02 | B27: Breach Notification | C27: Internal Verification & Scope Assessment | D27: Breach confirmed involving PD | E27: R | F27: A | G27: R | H27: R | I27: I | J27: I | K27: I | L27: I | M27: C | N27: C | O27: C | P27: I | Q27: P0 — Critical | R27: Phase 1
A28: BN-03 | B28: Breach Notification | C28: Notification to Affected Data Principals (Rule 7(1)) | D28: Required info available without delay | E28: R | F28: R | G28: A | H28: R | I28: I | J28: R | K28: I | L28: I | M28: R | N28: I | O28: I | P28: I | Q28: P0 — Critical | R28: Phase 1
A29: BN-04 | B29: Breach Notification | C29: First Intimation to Board (Rule 7(2)(a)) | D29: Immediately after breach-awareness | E29: R | F29: R | G29: A | H29: C | I29: I | J29: I | K29: I | L29: I | M29: C | N29: I | O29: I | P29: I | Q29: P0 — Critical | R29: Phase 1
A30: BN-05 | B30: Breach Notification | C30: Detailed Follow-Up Submission to Board (Rule 7(2)(b)) | D30: Within 72 hours | E30: R | F30: R | G30: A | H30: R | I30: I | J30: I | K30: I | L30: I | M30: C | N30: C | O30: C | P30: I | Q30: P0 — Critical | R30: Phase 1
A31: BN-06 | B31: Breach Notification | C31: Evidence Preservation & Retention | D31: Throughout breach handling | E31: R | F31: A | G31: R | H31: R | I31: I | J31: I | K31: I | L31: I | M31: C | N31: I | O31: R | P31: I | Q31: P0 — Critical | R31: Phase 1
A32: BN-07 | B32: Breach Notification | C32: Breach Notification During Retention / Pre-Erasure Period | D32: Breach during retention window | E32: R | F32: A | G32: R | H32: R | I32: I | J32: I | K32: I | L32: I | M32: C | N32: I | O32: R | P32: I | Q32: P1 — High | R32: Phase 2
A33: RETENTION & ERASURE
A34: RE-01 | B34: Retention & Erasure | C34: Applicability Confirmation (Third Schedule Class + Purpose) | D34: Org qualifies under Third Schedule | E34: A | F34: I | G34: R | H34: C | I34: I | J34: C | K34: I | L34: C | M34: R | N34: C | O34: I | P34: I | Q34: P1 — High | R34: Phase 1
A35: RE-02 | B35: Retention & Erasure | C35: Trigger for Purpose-Based Erasure | D35: No DP engagement for purpose | E35: A | F35: C | G35: R | H35: R | I35: I | J35: R | K35: I | L35: C | M35: R | N35: C | O35: R | P35: I | Q35: P1 — High | R35: Phase 2
A36: RE-03 | B36: Retention & Erasure | C36: Mandatory 48-Hour Pre-Erasure Notice | D36: 48hrs before scheduled erasure | E36: A | F36: I | G36: C | H36: R | I36: I | J36: R | K36: I | L36: I | M36: C | N36: I | O36: R | P36: I | Q36: P1 — High | R36: Phase 2
A37: RE-04 | B37: Retention & Erasure | C37: Minimum One-Year Statutory Retention (Rule 8(3)) | D37: Any PD processing | E37: A | F37: R | G37: R | H37: R | I37: C | J37: I | K37: C | L37: I | M37: C | N37: C | O37: R | P37: I | Q37: P0 — Critical | R37: Phase 1
A38: RE-05 | B38: Retention & Erasure | C38: Final Erasure Execution (Rule 8(1)+8(2)+8(3)) | D38: All erasure pre-conditions met | E38: A | F38: R | G38: C | H38: R | I38: I | J38: I | K38: C | L38: I | M38: C | N38: I | O38: R | P38: I | Q38: P1 — High | R38: Phase 2
A39: RE-06 | B39: Retention & Erasure | C39: Security Safeguard Overlay over Processors | D39: Throughout lifecycle incl. backup | E39: C | F39: A | G39: C | H39: R | I39: I | J39: I | K39: R | L39: I | M39: C | N39: I | O39: R | P39: I | Q39: P1 — High | R39: Phase 2
A40: CHILDREN & PWD DATA
...

Sheet Assessment + Implementation
A1: DPDP COMPLIANCE FRAMEWORK — DUAL ASSESSMENT & IMPLEMENTATION TRACKER
A2: Assessment Area: Current-state evaluation of control maturity | Implementation Area: Forward-looking action tracking toward compliance target state
A3: CONTROL IDENTIFICATION | K3: ASSESSMENT AREA (Current State) | P3: IMPLEMENTATION AREA (Target State) | V3: GOVERNANCE & EVIDENCE
A4: Sr. No. | B4: Control ID | C4: Category | D4: Priority | E4: DPDP Section | F4: Max Penalty | G4: Reference | H4: Role / Responsibility | I4: Compliance Header | J4: Compliance Measures | K4: Assessment Status | L4: Maturity Level | M4: Gap Identified | N4: Gap Description | O4: Risk Rating | P4: Impl. Status | Q4: Accountable Owner | R4: Target Date | S4: Action Plan / Remediation | T4: Budget Est. (INR) | U4: % Complete | V4: Evidence Status | W4: Evidence Artefact / Location | X4: Last Review Date | Y4: Reviewer Comments
A5: 1 | B5: CN-01 | C5: Consent & Notice | D5: Critical | E5: Sec. 4, 5, 6, Rule 3 | F5: ₹50 Cr | G5: Section 4, 5, 6, read with Rule 3 | H5: Data Fiduciary | I5: Identify Legal Basis for Processing (Consent or Legitimate Use) | J5: • Maintain Processing + Legal Basis Register • Classify each processing into Consent or Legitimate Use before execution • Disallow bundled, conditional, forced, misleading basis selection • Flag and approve purpose change via governance workflow | K5: Partially Compliant | L5: 2 | M5: Yes | N5: Legal basis register exists for 60% of processing activities. New product lines (launched Q4 2025) not yet mapped. No governance workflow for purpose changes. | O5: High | P5: In Progress | Q5: Head of Legal | R5: 46203 | S5: Complete processing inventory for new product lines. Deploy purpose-change approval workflow in GRC tool. Train product teams on legal basis classification. | T5: 1200000 | U5: 0.45 | V5: Collected | W5: Legal Basis Register v2.3 — SharePoint/Privacy/LegalBasis/ | X5: 46068 | Y5: Register needs expansion to cover 3 new product lines. Workflow tool RFP in progress.
A6: 2 | B6: CN-02 | C6: Consent & Notice | D6: High | E6: Sec. 4, 5, 6, Rule 3 | F6: ₹50 Cr | G6: Section 4, 5, 6, read with Rule 3 | H6: Data Fiduciary | I6: Display & Serve Mandatory Notice (Standalone Notice) | J6: • Use separate notice (not merged with T&Cs/marketing) • Capture timestamp + notice version displayed • Provide direct links to rights, grievance & withdrawal page • Ensure notice remains accessible after consent
A7: 3 | B7: CN-03 | C7: Consent & Notice | D7: Critical | E7: Sec. 4, 5, 6, Rule 3 | F7: ₹50 Cr | G7: Section 4, 5, 6, read with Rule 3 | H7: Data Fiduciary | I7: Obtain Valid Consent | J7: • Use explicit action (tick-box, signature, OTP, click-accept) • Store consent evidence log: DP ID, timestamp, notice version, purpose, method • Block processing until consent proof exists • Prohibit reuse for new purposes unless re-consented | K7: Non-Compliant | L7: 1 | M7: Yes | N7: Consent captured via pre-ticked checkboxes on legacy web forms. No consent evidence log. Consent reused across purposes without re-consent. | O7: Critical | P7: Planning | Q7: Head of Product | R7: 46265 | S7: Replace pre-ticked checkboxes with explicit opt-in. Deploy consent SDK with granular purpose selection. Build consent evidence log (DP ID, timestamp, version, purpose, method). | T7: 3500000 | U7: 0.1 | V7: Not Collected | X7: 46068 | Y7: Legacy forms require complete rebuild. SDK vendor shortlisted.
A8: 4 | B8: CN-04 | C8: Consent & Notice | D8: High | E8: Sec. 4, 5, 6, Rule 3 | F8: ₹50 Cr | G8: Section 4, 5, 6, read with Rule 3 | H8: Data Fiduciary | I8: Enable Consent Withdrawal & Stop Processing After Withdrawal | J8: • Provide easy withdrawal method equal to effort of giving consent • Trigger automated blocking of further processing • Notify processors + internal systems to disable access/processing • Maintain withdrawal log: timestamp, scope, impacted systems
A9: 5 | B9: CN-05 | C9: Consent & Notice | D9: High | E9: Sec. 4, 5, 6, Rule 3 | F9: ₹50 Cr | G9: Section 4, 5, 6, read with Rule 3 | H9: Data Fiduciary | I9: Maintain Notice Content & Presentation Standard | J9: • Maintain central notice template + version control repository • Conduct legal + UX clarity review before publishing • Publish separately from marketing, commercial terms, or disclaimers • Retain historical versions + publication logs
A10: 6 | B10: CM-01 | C10: Consent Manager | D10: Medium | E10: Sec. 6(9), Rule 4 | F10: ₹50 Cr | G10: Section 6(9) read with Rule 4 | H10: Consent Managers | I10: Eligibility & Application Filing | J10: • Prepare evidence for all Part A criteria (technical, security, operational, financial, governance) • Collect documentary proof as per Board-published checklist • Prepare system architecture, SOPs and support model
A11: 7 | B11: CM-02 | C11: Consent Manager | D11: Medium | E11: Sec. 6(9), Rule 4 | F11: ₹50 Cr | G11: Section 6(9) read with Rule 4 | H11: Consent Managers | I11: Board Evaluation & Decision | J11: • Maintain verifiable compliance documentation • Ensure alignment between documentation and actual operations • Keep audit logs ready for demonstration
A12: 8 | B12: CM-03 | C12: Consent Manager | D12: High | E12: Sec. 6(9), Rule 4 | F12: ₹50 Cr | G12: Section 6(9) read with Rule 4 | H12: Consent Managers | I12: Registered Consent Manager Operating Obligations | J12: • Implement secure, transparent consent lifecycle handling • Maintain neutrality and non-manipulative flow • Maintain audit-ready operational logs and uptime records
A13: 9 | B13: CM-04 | C13: Consent Manager | D13: Medium | E13: Sec. 6(9), Rule 4 | F13: ₹50 Cr | G13: Section 6(9) read with Rule 4 | H13: Consent Managers | I13: Non-Adherence & Corrective Action | J13: • Operate continuous compliance assurance framework (CCAF) • Perform quarterly internal control audits and evidence-based testing • Implement tracked remediation plan with accountable owners and closure proof • Maintain regulatory response file with artefacts, logs, and timeline trail
A14: 10 | B14: CM-05 | C14: Consent Manager | D14: Low | E14: Sec. 6(9), Rule 4 | F14: ₹50 Cr | G14: Section 6(9) read with Rule 4 | H14: Consent Managers | I14: Suspension or Cancellation Power | J14: • Maintain live Business Continuity & Service Continuity Framework • Establish regulated handover, exit and portability mechanism for data and consent records • Maintain immutable traceability logs for every consent lifecycle event • Define shutdown, escrow, archival & return-of-data playbooks • Maintain contractual exit clauses with processors and technical partners
A15: 11 | B15: CM-06 | C15: Consent Manager | D15: Low | E15: Sec. 6(9), Rule 4 | F15: ₹50 Cr | G15: Section 6(9) read with Rule 4 | H15: Consent Managers | I15: Mandatory Information Disclosure to Board | J15: • Maintain central evidence and document repository • Maintain version-controlled policies, logs, audit records, and incident reports • Adopt formal Board-response SOP with internal SLAs • Maintain traceable response documentation & authorised sign-off
A16: 12 | B16: SS-01 | C16: Security Safeguards | D16: Critical | E16: Sec. 8(5), Rule 6 | F16: ₹250 Cr | G16: Section 8(5) read with Rule 6 | H16: Data Fiduciary | I16: Implement Reasonable Security Safeguards | J16: • Maintain real-time data inventory & data-flow register including processors • Encrypt/mask/tokenise personal data at rest & in transit • Enforce role-based access, MFA, least-privilege & Just-in-Time access • Enable continuous monitoring, log retention & breach alerting • Implement backup & continuity aligned to criticality & restoration objectives • Include enforceable security clauses in all processor contracts • Maintain approved security policy, SOPs, and evidence repositories | K16: Partially Compliant | L16: 2 | M16: Yes | N16: Encryption at rest implemented (AES-256). MFA enforced for privileged access. Gaps: no centralised log retention policy, backup restoration testing not quarterly, processor security clauses incomplete in 4 of 12 contracts. | O16: Critical | P16: In Progress | Q16: CISO | R16: 46234 | S16: Implement centralised SIEM with 1-year log retention. Schedule quarterly backup restoration drills. Amend 4 processor contracts to include Rule 6 security clauses. | T16: 8500000 | U16: 0.55 | V16: Collected | W16: SIEM Config Docs — Confluence/Security/SIEM; Encryption Audit Report Feb 2026 | X16: 46073 | Y16: SIEM deployment 60% complete. Processor contract amendments drafted, pending legal review.
A17: 13 | B17: SS-02 | C17: Security Safeguards | D17: High | E17: Rule 6(b), 6(c) | F17: ₹250 Cr | G17: Rule 6(b), 6(c) | H17: Data Fiduciary | I17: Access Control & Monitoring | J17: • Enforce role-based, context-based, and least-privilege access assignments • Enforce MFA & strong authentication for privileged and remote access • Maintain logged workflow for access requests, approvals, revocations, & periodic certification • Implement real-time monitoring & anomaly alerting • Conduct quarterly access control & log review with documented outcomes
A18: 14 | B18: SS-03 | C18: Security Safeguards | D18: High | E18: Rule 6(d) | F18: ₹250 Cr | G18: Rule 6(d) | H18: Data Fiduciary | I18: Data Availability, Integrity & Backup Measures | J18: • Maintain encrypted and integrity-verified backups including both online and offline copies based on data criticality • Store critical data copies in a tamper-resistant, offline, or isolated (air-gapped) environment • Maintain a documented Business Continuity Plan and Disaster Recovery Plan (BCP/DRP) with clearly defined restoration timelines and recovery expectations • Conduct quarterly data restoration, failover, and disaster simulation testing with evidence • Use checksum or cryptographic ha
A19: 15 | B19: SS-04 | C19: Security Safeguards | D19: High | E19: Rule 6(e) | F19: ₹250 Cr | G19: Rule 6(e) | H19: Data Fiduciary | I19: Log Retention & Breach Detection Visibility | J19: • Maintain a centralised, tamper-resistant logging system covering user activity, system events, and data access • Protect logs using write-once or restricted-permission storage controls so they cannot be altered or deleted • Enable real-time alerting and correlation rules to identify abnormal behaviour • Maintain an incident investigation and evidence-preservation workflow with time-stamped triage records • Retain incident-related logs separately until closure of investigation, legal hold, or r
A20: 16 | B20: SS-05 | C20: Security Safeguards | D20: High | E20: Rule 6(f) | F20: ₹250 Cr | G20: Rule 6(f) | H20: Data Fiduciary | I20: Security Obligations in Processor Contracts | J20: • Draft and enforce mandatory data protection and security clauses including: encryption, secure access management, logging, monitoring, incident reporting timelines, data return/deletion terms, subcontracting restrictions, and audit/cooperation rights • Perform documented due-diligence and periodic risk assessments on every Data Processor • Maintain evidence repository including contract versions, evaluation records, risk scores, and remediation reports
A21: 17 | B21: SS-06 | C21: Security Safeguards | D21: Medium | E21: Rule 6(g) | F21: ₹250 Cr | G21: Rule 6(g) | H21: Data Fiduciary | I21: Technical & Organisational Measures (Ongoing) | J21: • Operate a continuous compliance and threat monitoring function • Conduct scheduled security assessments, penetration testing, and configuration reviews • Maintain secure software development lifecycle (SSDLC) controls for product and feature releases • Ensure mandatory periodic security and privacy training for all relevant personnel • Record evidence-based audit trails of testing, remediation and control maturity improvements
A22: 18 | B22: BN-01 | C22: Breach Notification | D22: Critical | E22: Sec. 8(6), Rule 7(1), 7(2) | F22: ₹200 Cr | G22: Section 8(6) read with Rule 7(1) & Rule 7(2) | H22: Data Fiduciary | I22: Breach Awareness & Activation (Including Processor-Caused Breach) | J22: • Contractually mandate immediate breach reporting SLA from Processor to Data Fiduciary (example: within two hours of detection) • Integrate Processor incident escalation into incident response playbooks and information security management procedures • Establish single, logged intake channel for all Processor breach submissions • Maintain forensic-grade evidence and chain-of-custody records, even if evidence originates from Processor-owned infrastructure | K22: Non-Compliant | L22: 0 | M22: Yes | N22: No documented breach response playbook. Processor contracts lack breach reporting SLAs. No forensic evidence chain-of-custody protocol. Ad-hoc incident handling only. | O22: Critical | P22: Planning | Q22: CISO | R22: 46295 | S22: Develop breach response playbook aligned to Rule 7. Mandate 2-hour processor breach reporting SLA in all contracts. Establish forensic evidence preservation protocol. Conduct tabletop simulation. | T22: 2000000 | U22: 0.05 | V22: Not Collected | X22: 46068 | Y22: Critical gap. Board briefed. Playbook development starting March 2026.
A23: 19 | B23: BN-02 | C23: Breach Notification | D23: High | E23: Sec. 8(6), Rule 7(1)(a-e), 7(2)(a) | F23: ₹200 Cr | G23: Section 8(6) read with Rule 7(1)(a)–(e) & Rule 7(2)(a) | H23: Data Fiduciary | I23: Initial Internal Verification & Scope Assessment | J23: • Activate documented breach assessment runbook • Classify impacted data type, identifiability, volume, and potential harm indicators • Validate and evidence Processor-side logs, configurations, and timestamps • Record two timestamps separately: (i) time of breach occurrence/detection, (ii) time of awareness by Fiduciary • Maintain authoritative registry of user communication channels and delivery preferences for notification execution
A24: 20 | B24: BN-03 | C24: Breach Notification | D24: High | E24: Sec. 8(6), Rule 7(1)(a-e) | F24: ₹200 Cr | G24: Section 8(6) read with Rule 7(1)(a)–€ | H24: Data Fiduciary | I24: Notification to Affected Data Principals | J24: • Maintain pre-approved notification templates aligned to each clause of Rule 7(1)(a)–(e) • Use verified and active communication channel such as registered email, SMS, in-app notification, or account dashboard • Retain proof of delivery, read-status where feasible, and escalation log for unreachable individuals
A25: 21 | B25: BN-04 | C25: Breach Notification | D25: High | E25: Sec. 8(6), Rule 7(2)(a) | F25: ₹200 Cr | G25: Section 8(6) read with Rule 7(2)(a) | H25: Data Fiduciary | I25: First Intimation to the Board | J25: • Use pre-approved regulatory reporting template • Ensure authorised sign-off (not below designated senior compliance / privacy officer) • Capture exact timestamp of awareness and submission • Store acknowledgement and follow-up references • Clearly disclose whether the breach originated from Processor environment
A26: 22 | B26: BN-05 | C26: Breach Notification | D26: High | E26: Sec. 8(6), Rule 7(2)(b) | F26: ₹200 Cr | G26: Section 8(6) read with Rule 7(2)(b)(i)–(vi) | H26: Data Fiduciary | I26: Detailed Follow-Up Submission to Board | J26: • Obtain complete event timeline, technical logs, forensics evidence and incident artefacts (including from Processor) • Conduct structured Root-Cause-Analysis with named accountable owners • Submit corrective action plan with milestones and validation criteria • Attach evidence repository including Data Principal notification proof, Processor breach documentation and chain-of-custody trail
A27: 23 | B27: BN-06 | C27: Breach Notification | D27: High | E27: Sec. 8(6), Rule 7 | F27: ₹200 Cr | G27: Section 8(6) read with Rule 7(1) & Rule 7(2) | H27: Data Fiduciary | I27: Evidence Preservation & Retention | J27: • Maintain tamper-resistant preservation of all incident artefacts including logs, alerts, communication records, forensics outputs, screenshots, tickets, emails and investigation minutes • Require Processor to retain and supply logs and artefacts in original, unaltered form • Maintain separate, access-controlled incident evidence repository with immutability controls for regulatory and audit reference
A28: 24 | B28: RE-01 | C28: Retention & Erasure | D28: Medium | E28: Rule 8(1) | F28: ₹50 Cr | G28: Rule 8(1) | H28: Data Fiduciary (E-Commerce, E-Gaming & Social Media Intermediary) | I28: Applicability Confirmation (Class + Purpose) | J28: • Conduct and document classification assessment with evidence • Maintain purpose-to-class mapping and review on any change • Track user-population / business-model changes that may alter classification • Maintain periodic re-validation record for all active processing purposes
A29: 25 | B29: RE-02 | C29: Retention & Erasure | D29: Medium | E29: Rule 8(1) | F29: ₹50 Cr | G29: Rule 8(1) | H29: Data Fiduciary (E-Commerce, E-Gaming & Social Media Intermediary) | I29: Trigger for Purpose-Based Erasure | J29: • Maintain objectively recorded last-interaction timestamp • Configure purpose-specific retention timers • Prevent non-DP-initiated auto-renewal events • Ensures confirmation based Deletion/Account Removals.
A30: 26 | B30: RE-03 | C30: Retention & Erasure | D30: Medium | E30: Rule 8(2) | F30: ₹50 Cr | G30: Rule 8(2) | H30: Data Fiduciary (E-Commerce, E-Gaming & Social Media Intermediary) | I30: Mandatory 48-Hour Pre-Erasure Notice | J30: • Maintain verifiable, system-generated last-interaction timestamp tied to the specific purpose • Configure purpose-specific, non-extendable retention timers mapped to Third Schedule requirements • Disable auto-renewal, auto-login, passive reactivation or inferred-activity extensions that would silently prolong retention • Implement confirmed-erasure workflow including account-level and dataset-level deletion acknowledgements
A31: 27 | B31: RE-04 | C31: Retention & Erasure | D31: High | E31: Sec. 8(5), Rule 8(3) | F31: ₹50 Cr | G31: Section 8(5) read with Rule 8(3) | H31: Data Fiduciary | I31: Rule 8(3) – Minimum One-Year Statutory Retention | J31: • Maintain a central retention register capturing data category, source, purpose, legal retention basis, retention start date and minimum mandated end-date • Update processor contracts and SoWs to include minimum 1-year retention, controlled deletion timeline and evidentiary delivery obligations • Ensure archival, DR, and backup systems enforce the same retention controls • Disallow deletion requests unless supported by Seventh Schedule justification and post-minimum-period eligibility | K31: Compliant | L31: 3 | M31: No | O31: Low | P31: Implemented | Q31: Head of IT | R31: 46053 | S31: Central retention register deployed. Minimum 1-year retention enforced across all systems. Processor contracts updated with retention clauses. | T31: 500000 | U31: 1 | V31: Validated | W31: Retention Register v1.0 — GRC Platform; Processor Contract Addendums — Legal/Contracts/ | X31: 46053 | Y31: Fully implemented and validated by internal audit Jan 2026.
A32: 28 | B32: RE-05 | C32: Retention & Erasure | D32: Medium | E32: Sec. 8(5), 12(3), Rule 8 | F32: ₹50 Cr | G32: Section 8(5) read with Section 12(3) read with Rule 8(1), 8(2), 8(3) | H32: Data Fiduciary | I32: Rule 8(1) + 8(2) + 8(3) – Final Erasure Execution | J32: • Use a controlled erasure workflow (no masking, anonymisation, or reversible soft-delete counted as erasure) • Capture tamper-proof audit evidence: request ID, authoriser, timestamp, data scope, and system-level confirmation • Obtain deletion proof from processors and sub-processors including backup repositories • Conduct erasure reconciliation checks to confirm no residual artefacts remain in logs, caches, analytics, shadow storages.
A33: 29 | B33: RE-06 | C33: Security Safeguards | D33: High | E33: Sec. 8(5), Rule 6 | F33: ₹250 Cr | G33: Section 8(5) read with Rule 6 | H33: Data Fiduciary | I33: Security Safeguard Overlay over Processors | J33: • Apply full security safeguards consistently across live, mirrored, archived, dormant, backup, and pre-erasure environments • Conduct periodic privileged access review, log audit and processor security performance validation • Enforce ongoing contractual compliance including evidence-based controls testing for all processors and sub-processors
A34: 30 | B34: BN-07 | C34: Breach Notification | D34: Medium | E34: Sec. 8(5), Rule 7 | F34: ₹200 Cr | G34: Section 8(5) read with Rule 7 | H34: Data Fiduciary | I34: Breach Notification During Retention / Inactivity / Pre-Erasure Period | J34: • Extend breach-response SOP and incident classification matrix to include archived, inactive, dormant, cold-storage and backup environments • Mandate contractual breach reporting SLA for processors and sub-processors aligned to fiduciary timelines • Maintain legally defensible, searchable, and tamper-proof logs for the full duration of the retention period
A35: 31 | B35: CP-01 | C35: Contact & Publication | D35: Medium | E35: Sec. 8(9), Rule 9 | F35: ₹50 Cr | G35: Section 8(9) read with Rule 9 | H35: Data Fiduciary | I35: Contact Information Publication Obligation | J35: • Publish a single official and monitored contact point (not generic marketing, customer support, ticket-bot or promotional addresses) • Place contact information in mandatory visibility zones (footer, privacy notice, rights response templates, app settings) • Verify publication accessibility for all user categories including non-logged-in users • Maintain training and internal escalation path for query resolution with service levels recorded in policy | K35: Compliant | L35: 4 | M35: No | O35: Low | P35: Verified | Q35: DPO | R35: 46006 | S35: Dedicated privacy contact published on website footer, app settings, and all privacy notices. Monthly reachability audit in place. | T35: 100000 | U35: 1 | V35: Audit-Ready | W35: Website Footer Screenshot Dec 2025; App Settings Screenshot; Privacy Notice v3.1 — SharePoint/Privacy/ | X35: 46037 | Y35: Verified by external auditor. No findings.
A36: 32 | B36: CP-02 | C36: Contact & Publication | D36: Medium | E36: Sec. 10(2), Rule 9 | F36: ₹50 Cr | G36: Section 10(2) read with Rule 9 | H36: Data Fiduciary | I36: Applicability of DPO Contact Requirement | J36: • Conduct internal and documented assessment of classification under Section 10 criteria • If classified as Significant Data Fiduciary → appoint Data Protection Officer and publish the contact • If not classified as Significant Data Fiduciary → assign and publish a trained, accountable and authorised contact person • Periodically revalidate classification status
A37: 33 | B37: CD-02 | C37: Children & Exemptions | D37: Low | E37: Sec. 9(4), 12(2) | F37: ₹200 Cr | G37: Section 9(4) read with Section 12(2) | H37: Data Fiduciary is a clinical establishment / mental health establishment / healthcare professional / Child-Care Centre/Creche/ Educational Institutions | I37: Exception Based on Class of Data Fiduciary | J37: • Document and approve class-eligibility mapping referencing Fourth Schedule language • Bind processing purpose to permitted scenario using access-control + architectural controls • Maintain necessity + proportionality evidence and periodic review trail
A38: 34 | B38: CD-03 | C38: Children & Exemptions | D38: Low | E38: Sec. 9(4), 12(2) | F38: ₹200 Cr | G38: Section 9(4) read with Section 12(2) | H38: Data Fiduciary | I38: Exception Based on Purpose | J38: • Apply purpose-matching test prior to invocation • Record purpose code, statutory basis, and necessity/proportionality justification • Maintain documentation evidencing minimal-use alignment • Hard-block scope extension, feature-addition and repurposing • Enforce periodic legal-basis re-validation for continued eligibility
A39: 35 | B39: CD-01 | C39: Children & Exemptions | D39: Critical | E39: Sec. 8(5), Rule 10 | F39: ₹200 Cr | G39: Section 8(5) read with Rule 10 | H39: Data Fiduciary | I39: Data Protection & Security Safeguards for Child Data | J39: • Implement child-specific hardened controls including encryption, segregated repositories, multi-factor authentication, tamper-resistant audit logs • Conduct structured periodic control testing with evidentiary documentation | K39: Non-Compliant | L39: 0 | M39: Yes | N39: No age-verification mechanism. No child-specific data segregation. Standard security controls applied uniformly — no hardened child-data protections. No parental consent workflow. | O39: Critical | P39: Not Started | Q39: Head of Product | R39: 46326 | S39: Implement age-gate with Rule 10 verification. Build parental consent workflow. Segregate child data repositories with enhanced encryption and MFA. Deploy tamper-resistant audit logs. | T39: 5000000 | U39: 0 | V39: Not Collected | X39: 46068 | Y39: ₹200 Cr penalty exposure. Requires significant product and infrastructure changes. Board approval needed for budget.
A40: 36 | B40: CD-04 | C40: Children & Exemptions | D40: Low | E40: Sec. 9(4), 12(1) | F40: ₹200 Cr | G40: Sec 9(4) read with Sec 12(1) | H40: Data Fiduciary under 4th Schedule hospital | I40: Exception Based on Class of Data Fiduciary | J40: Maintain documented evidence establishing correct classification under Part-A • Preserve purpose-to-schedule mapping record and necessity assessment • Prevent scope expansion, behavioural analytics, or any unrelated derivation use • Maintain evidence repository including SOPs, notices, Data Protection Impact Assessment notes, logs, and risk justification • Conduct periodic eligibility verification and re-qualification triggered by role, service, technology, vendor, or contractual change
...

Sheet Granular Controls
A1: DPDP COMPLIANCE FRAMEWORK — GRANULAR CONTROL ASSESSMENT WITH TRACKING
A2: Sr. No. | B2: Ref. Act | C2: Ref. Rule | D2: Act Description | E2: Rule Description | F2: Nature of Activity | G2: Applicability | H2: Assessment Status | I2: Maturity Level | J2: Impl. Status | K2: Accountable Owner | L2: Target Date | M2: Risk Rating | N2: Evidence Status
A3: A1.1 | B3: Sec 5(1) | C3: Rule 4(1) | D3: Notice must describe categories of personal data and the purpose before/with consent. | E3: Mandatory notice elements including purpose, data categories, rights, grievance details. | F3: Draft and Serve Privacy Notice | G3: DF + SDF
A4: A1.2 | B4: Sec 5(1)(ii) | C4: Rule 4(2)(a) | D4: Notice must inform DP of rights under Sec 6(4) and Sec 13. | E4: DF must publish DP rights mechanisms. | F4: Publish Rights Exercise Procedure | G4: DF + SDF
A5: A1.3 | B5: Sec 5(1)(iii) | C5: Rule 4(2)(b) | D5: Notice must specify grievance mechanism and contact. | E5: DF must publish grievance timelines + contacts within 90 days. | F5: Publish Grievance Redress Details | G5: DF + SDF
A6: A1.4 | B6: Sec 5(3) | C6: Rule 4(1) | D6: Notice must be available in English or Eighth Schedule language. | E6: Supports multilingual availability. | F6: Multilingual Notice Availability | G6: DF + SDF
A7: A1.5 | B7: Sec 5(2) | C7: Rule 4(3) | D7: DF must issue fresh notice for pre-Act consent. | E7: Sets format/timeline for legacy notices. | F7: Legacy Consent Notice Issuance | G7: DF + SDF
A8: A1.6 | B8: Sec 5 | C8: Rule 14(1) | D8: Notice must include DF/DPO contact info. | E8: Requires publication on website/app. | F8: Publish DF/DPO Contact Details | G8: DF + SDF
A9: A1.7 | B9: Sec 5 + Sec 6(3) | C9: Rule 4 | D9: Notice must be separate from T&Cs and clearly structured. | E9: Rule enforces clarity and plain language. | F9: Separate Notice from T&Cs | G9: DF + SDF
A10: Sr. No. (A2 — Consent Requirements)
A11: A2.1 | B11: Sec 6(1) | C11: — | D11: Consent must be free, specific, informed, unambiguous, affirmative. | E11: — | F11: Valid Consent Capture | G11: DF + SDF
A12: A2.2 | B12: Sec 6(1) | C12: Rule 4 | D12: Consent must be purpose-limited. | E12: Rule supports segmentation of notice items. | F12: Purpose-limited Consent Design | G12: DF + SDF
A13: A2.3 | B13: Sec 6(2) | C13: — | D13: Any unlawful portion of consent is void. | E13: — | F13: Consent Validity Review | G13: DF + SDF
A14: A2.4 | B14: Sec 6(3) | C14: Rule 4 | D14: Consent request must be clear, plain language. | E14: Rule mandates simple and readable format. | F14: Plain-language Consent Request | G14: DF + SDF
A15: A2.5 | B15: Sec 6(3) | C15: Rule 4 | D15: Consent request must include DF/DPO contact. | E15: Requires accessible publication. | F15: Include Contact in Consent Request | G15: DF + SDF
A16: A2.6 | B16: Sec 6(4) | C16: Rule 14 | D16: Withdrawal must be as easy as giving consent. | E16: Requires DF to publish mechanism within 90 days. | F16: Consent Withdrawal Mechanism | G16: DF + SDF
A17: A2.7 | B17: Sec 6(5) | C17: — | D17: DF must stop processing when consent withdrawn unless legally required otherwise. | E17: — | F17: Stop Processing After Withdrawal | G17: DF + SDF
A18: A2.8 | B18: Sec 6(6) | C18: Rule 8 | D18: DF must ensure processors cease processing on withdrawal. | E18: Rule ties this to erasure obligations. | F18: Processor Cessation Instruction | G18: DF (via contract)
A19: A2.9 | B19: Sec 6(7) | C19: Rule 7 | D19: DP may use a Consent Manager to give/manage consent. | E19: Rule defines Consent Manager duties + registration. | F19: Integrate Consent Manager | G19: DF + SDF
A20: A2.10 | B20: Sec 6(8) | C20: Rule 7 | D20: Consent Managers must act only on DP instructions; accountable to DP. | E20: Rule outlines CM transparency + logs. | F20: Ensure CM Accountability | G20: Consent Manager
A21: A2.11 | B21: Sec 6(10) | C21: — | D21: DF must prove notice + consent validity if challenged. | E21: — | F21: Maintain Consent Logs & Evidence | G21: DF + SDF
A22: Sr. No. (A3 — Voluntary Data Supply)
A23: A3.1 | B23: Sec 7(a) | C23: Rule 4 | D23: DF may process voluntarily supplied data for a specific purpose unless DP objects. | E23: Notice obligations still apply for voluntary data. | F23: Voluntary Data Processing | G23: DF + SDF
A24: A3.2 | B24: Sec 7(a) Illustration | C24: — | D24: DF must cease processing when DP objects. | E24: — | F24: Opt-out Handling | G24: DF + SDF
A25: Sr. No. (A4 — Children / PWD Requirements)
A26: A4.1 | B26: Sec 9(1) | C26: Rule 12 | D26: Must obtain verifiable parental/guardian consent before processing child/PWD data. | E26: Sets verification rules + exemptions (Fourth Schedule). | F26: Parental/Guardian Consent Mechanism | G26: DF + SDF
A27: A4.2 | B27: Sec 9(3) | C27: Fourth Schedule | D27: No tracking, monitoring, profiling, targeted ads for children. | E27: Fourth Schedule exemptions for safety/education. | F27: Child-protective Processing Controls | G27: DF + SDF
A28: Sr. No. (A5 — Publication & Accessibility Requirements)
A29: A5.1 | B29: Sec 5(3) | C29: Rule 14 | D29: Notice must be in English or Eighth Schedule language. | E29: Requires DF to publish grievance + rights info. | F29: Multilingual Publication | G29: DF + SDF
